2020-01-13 09:48:54,420 - root - ERROR - Traceback (most recent call last):

2020-01-13 09:48:54,420 - root - ERROR - Traceback (most recent call last):

2020-01-13 09:48:54,420 - root - ERROR - Traceback (most recent call last):

2020-01-13 09:48:54,420 - root - ERROR - Traceback (most recent call last):

2020-01-13 09:48:54,420 - root - ERROR - Traceback (most recent call last):

2020-01-13 09:48:54,420 - root - ERROR - Traceback (most recent call last):

2020-01-13 09:48:54,420 - root - ERROR - Traceback (most recent call last):

2020-01-13 09:48:54,420 - root - ERROR - Traceback (most recent call last):

2020-01-13 09:48:54,420 - root - ERROR - Traceback (most recent call last):

2020-01-13 09:48:54,420 - root - ERROR - Traceback (most recent call last):

2020-01-13 09:48:54,420 - root - ERROR - Traceback (most recent call last):

2020-01-13 09:48:54,420 - root - ERROR - Traceback (most recent call last):

2020-01-13 09:48:54,420 - root - ERROR - Traceback (most recent call last):

2020-01-13 09:48:54,420 - root - ERROR - Traceback (most recent call last):

2020-01-13 09:48:54,420 - root - ERROR -   File "service_book.pyw", line 2227, in <module>

2020-01-13 09:48:54,420 - root - ERROR -   File "service_book.pyw", line 2227, in <module>

2020-01-13 09:48:54,420 - root - ERROR -   File "service_book.pyw", line 2227, in <module>

2020-01-13 09:48:54,420 - root - ERROR -   File "service_book.pyw", line 2227, in <module>

2020-01-13 09:48:54,420 - root - ERROR -   File "service_book.pyw", line 2227, in <module>

2020-01-13 09:48:54,420 - root - ERROR -   File "service_book.pyw", line 2227, in <module>

2020-01-13 09:48:54,420 - root - ERROR -   File "service_book.pyw", line 2227, in <module>

2020-01-13 09:48:54,420 - root - ERROR -   File "service_book.pyw", line 2227, in <module>

2020-01-13 09:48:54,420 - root - ERROR -   File "service_book.pyw", line 2227, in <module>

2020-01-13 09:48:54,420 - root - ERROR -   File "service_book.pyw", line 2227, in <module>

2020-01-13 09:48:54,420 - root - ERROR -   File "service_book.pyw", line 2227, in <module>

2020-01-13 09:48:54,420 - root - ERROR -   File "service_book.pyw", line 2227, in <module>

2020-01-13 09:48:54,420 - root - ERROR -   File "service_book.pyw", line 2227, in <module>

2020-01-13 09:48:54,420 - root - ERROR -   File "service_book.pyw", line 2227, in <module>

2020-01-13 09:48:54,420 - root - ERROR -   File "service_book.pyw", line 317, in vp_start_gui

2020-01-13 09:48:54,420 - root - ERROR -   File "service_book.pyw", line 317, in vp_start_gui

2020-01-13 09:48:54,420 - root - ERROR -   File "service_book.pyw", line 317, in vp_start_gui

2020-01-13 09:48:54,420 - root - ERROR -   File "service_book.pyw", line 317, in vp_start_gui

2020-01-13 09:48:54,420 - root - ERROR -   File "service_book.pyw", line 317, in vp_start_gui

2020-01-13 09:48:54,420 - root - ERROR -   File "service_book.pyw", line 317, in vp_start_gui

2020-01-13 09:48:54,420 - root - ERROR -   File "service_book.pyw", line 317, in vp_start_gui

2020-01-13 09:48:54,420 - root - ERROR -   File "service_book.pyw", line 317, in vp_start_gui

2020-01-13 09:48:54,420 - root - ERROR -   File "service_book.pyw", line 317, in vp_start_gui

2020-01-13 09:48:54,420 - root - ERROR -   File "service_book.pyw", line 317, in vp_start_gui

2020-01-13 09:48:54,420 - root - ERROR -   File "service_book.pyw", line 317, in vp_start_gui

2020-01-13 09:48:54,420 - root - ERROR -   File "service_book.pyw", line 317, in vp_start_gui

2020-01-13 09:48:54,420 - root - ERROR -   File "service_book.pyw", line 317, in vp_start_gui

2020-01-13 09:48:54,420 - root - ERROR -   File "service_book.pyw", line 317, in vp_start_gui

2020-01-13 09:48:54,420 - root - ERROR -   File "service_book.pyw", line 404, in __init__

2020-01-13 09:48:54,420 - root - ERROR -   File "service_book.pyw", line 404, in __init__

2020-01-13 09:48:54,420 - root - ERROR -   File "service_book.pyw", line 404, in __init__

2020-01-13 09:48:54,420 - root - ERROR -   File "service_book.pyw", line 404, in __init__

2020-01-13 09:48:54,420 - root - ERROR -   File "service_book.pyw", line 404, in __init__

2020-01-13 09:48:54,420 - root - ERROR -   File "service_book.pyw", line 404, in __init__

2020-01-13 09:48:54,420 - root - ERROR -   File "service_book.pyw", line 404, in __init__

2020-01-13 09:48:54,420 - root - ERROR -   File "service_book.pyw", line 404, in __init__

2020-01-13 09:48:54,420 - root - ERROR -   File "service_book.pyw", line 404, in __init__

2020-01-13 09:48:54,420 - root - ERROR -   File "service_book.pyw", line 404, in __init__

2020-01-13 09:48:54,420 - root - ERROR -   File "service_book.pyw", line 404, in __init__

2020-01-13 09:48:54,420 - root - ERROR -   File "service_book.pyw", line 404, in __init__

2020-01-13 09:48:54,420 - root - ERROR -   File "service_book.pyw", line 404, in __init__

2020-01-13 09:48:54,420 - root - ERROR -   File "service_book.pyw", line 404, in __init__

2020-01-13 09:48:54,420 - root - ERROR -   File "tkinter\__init__.py", line 2071, in wm_iconbitmap

2020-01-13 09:48:54,420 - root - ERROR -   File "tkinter\__init__.py", line 2071, in wm_iconbitmap

2020-01-13 09:48:54,420 - root - ERROR -   File "tkinter\__init__.py", line 2071, in wm_iconbitmap

2020-01-13 09:48:54,420 - root - ERROR -   File "tkinter\__init__.py", line 2071, in wm_iconbitmap

2020-01-13 09:48:54,420 - root - ERROR -   File "tkinter\__init__.py", line 2071, in wm_iconbitmap

2020-01-13 09:48:54,420 - root - ERROR -   File "tkinter\__init__.py", line 2071, in wm_iconbitmap

2020-01-13 09:48:54,420 - root - ERROR -   File "tkinter\__init__.py", line 2071, in wm_iconbitmap

2020-01-13 09:48:54,420 - root - ERROR -   File "tkinter\__init__.py", line 2071, in wm_iconbitmap

2020-01-13 09:48:54,420 - root - ERROR -   File "tkinter\__init__.py", line 2071, in wm_iconbitmap

2020-01-13 09:48:54,420 - root - ERROR -   File "tkinter\__init__.py", line 2071, in wm_iconbitmap

2020-01-13 09:48:54,420 - root - ERROR -   File "tkinter\__init__.py", line 2071, in wm_iconbitmap

2020-01-13 09:48:54,420 - root - ERROR -   File "tkinter\__init__.py", line 2071, in wm_iconbitmap

2020-01-13 09:48:54,420 - root - ERROR -   File "tkinter\__init__.py", line 2071, in wm_iconbitmap

2020-01-13 09:48:54,420 - root - ERROR -   File "tkinter\__init__.py", line 2071, in wm_iconbitmap

2020-01-13 09:48:54,420 - root - ERROR - _tkinter
2020-01-13 09:48:54,420 - root - ERROR - _tkinter
2020-01-13 09:48:54,420 - root - ERROR - _tkinter
2020-01-13 09:48:54,420 - root - ERROR - _tkinter
2020-01-13 09:48:54,420 - root - ERROR - _tkinter
2020-01-13 09:48:54,420 - root - ERROR - _tkinter
2020-01-13 09:48:54,420 - root - ERROR - _tkinter
2020-01-13 09:48:54,420 - root - ERROR - _tkinter
2020-01-13 09:48:54,420 - root - ERROR - _tkinter
2020-01-13 09:48:54,420 - root - ERROR - _tkinter
2020-01-13 09:48:54,420 - root - ERROR - _tkinter
2020-01-13 09:48:54,420 - root - ERROR - _tkinter
2020-01-13 09:48:54,420 - root - ERROR - _tkinter
2020-01-13 09:48:54,420 - root - ERROR - _tkinter
2020-01-13 09:48:54,420 - root - ERROR - .
2020-01-13 09:48:54,420 - root - ERROR - .
2020-01-13 09:48:54,420 - root - ERROR - .
2020-01-13 09:48:54,420 - root - ERROR - .
2020-01-13 09:48:54,420 - root - ERROR - .
2020-01-13 09:48:54,420 - root - ERROR - .
2020-01-13 09:48:54,420 - root - ERROR - .
2020-01-13 09:48:54,420 - root - ERROR - .
2020-01-13 09:48:54,420 - root - ERROR - .
2020-01-13 09:48:54,420 - root - ERROR - .
2020-01-13 09:48:54,420 - root - ERROR - .
2020-01-13 09:48:54,420 - root - ERROR - .
2020-01-13 09:48:54,420 - root - ERROR - .
2020-01-13 09:48:54,420 - root - ERROR - .
2020-01-13 09:48:54,420 - root - ERROR - TclError
2020-01-13 09:48:54,420 - root - ERROR - TclError
2020-01-13 09:48:54,420 - root - ERROR - TclError
2020-01-13 09:48:54,420 - root - ERROR - TclError
2020-01-13 09:48:54,420 - root - ERROR - TclError
2020-01-13 09:48:54,420 - root - ERROR - TclError
2020-01-13 09:48:54,420 - root - ERROR - TclError
2020-01-13 09:48:54,420 - root - ERROR - TclError
2020-01-13 09:48:54,420 - root - ERROR - TclError
2020-01-13 09:48:54,420 - root - ERROR - TclError
2020-01-13 09:48:54,420 - root - ERROR - TclError
2020-01-13 09:48:54,420 - root - ERROR - TclError
2020-01-13 09:48:54,420 - root - ERROR - TclError
2020-01-13 09:48:54,420 - root - ERROR - TclError
2020-01-13 09:48:54,420 - root - ERROR - : 
2020-01-13 09:48:54,420 - root - ERROR - : 
2020-01-13 09:48:54,420 - root - ERROR - : 
2020-01-13 09:48:54,420 - root - ERROR - : 
2020-01-13 09:48:54,420 - root - ERROR - : 
2020-01-13 09:48:54,420 - root - ERROR - : 
2020-01-13 09:48:54,420 - root - ERROR - : 
2020-01-13 09:48:54,420 - root - ERROR - : 
2020-01-13 09:48:54,420 - root - ERROR - : 
2020-01-13 09:48:54,420 - root - ERROR - : 
2020-01-13 09:48:54,420 - root - ERROR - : 
2020-01-13 09:48:54,420 - root - ERROR - : 
2020-01-13 09:48:54,420 - root - ERROR - : 
2020-01-13 09:48:54,420 - root - ERROR - : 
2020-01-13 09:48:54,420 - root - ERROR - bitmap "icons/icon.ico" not defined
2020-01-13 09:48:54,420 - root - ERROR - bitmap "icons/icon.ico" not defined
2020-01-13 09:48:54,420 - root - ERROR - bitmap "icons/icon.ico" not defined
2020-01-13 09:48:54,420 - root - ERROR - bitmap "icons/icon.ico" not defined
2020-01-13 09:48:54,420 - root - ERROR - bitmap "icons/icon.ico" not defined
2020-01-13 09:48:54,420 - root - ERROR - bitmap "icons/icon.ico" not defined
2020-01-13 09:48:54,420 - root - ERROR - bitmap "icons/icon.ico" not defined
2020-01-13 09:48:54,420 - root - ERROR - bitmap "icons/icon.ico" not defined
2020-01-13 09:48:54,420 - root - ERROR - bitmap "icons/icon.ico" not defined
2020-01-13 09:48:54,420 - root - ERROR - bitmap "icons/icon.ico" not defined
2020-01-13 09:48:54,420 - root - ERROR - bitmap "icons/icon.ico" not defined
2020-01-13 09:48:54,420 - root - ERROR - bitmap "icons/icon.ico" not defined
2020-01-13 09:48:54,420 - root - ERROR - bitmap "icons/icon.ico" not defined
2020-01-13 09:48:54,420 - root - ERROR - bitmap "icons/icon.ico" not defined
2020-01-13 09:48:54,420 - root - ERROR - 

2020-01-13 09:48:54,420 - root - ERROR - 

2020-01-13 09:48:54,420 - root - ERROR - 

2020-01-13 09:48:54,420 - root - ERROR - 

2020-01-13 09:48:54,420 - root - ERROR - 

2020-01-13 09:48:54,420 - root - ERROR - 

2020-01-13 09:48:54,420 - root - ERROR - 

2020-01-13 09:48:54,420 - root - ERROR - 

2020-01-13 09:48:54,420 - root - ERROR - 

2020-01-13 09:48:54,420 - root - ERROR - 

2020-01-13 09:48:54,420 - root - ERROR - 

2020-01-13 09:48:54,420 - root - ERROR - 

2020-01-13 09:48:54,420 - root - ERROR - 

2020-01-13 09:48:54,420 - root - ERROR - 

2020-01-13 09:50:14,984 - root - ERROR - Exception in Tkinter callback
2020-01-13 09:50:14,984 - root - ERROR - Exception in Tkinter callback
2020-01-13 09:50:14,984 - root - ERROR - Exception in Tkinter callback
2020-01-13 09:50:14,984 - root - ERROR - Exception in Tkinter callback
2020-01-13 09:50:14,984 - root - ERROR - Exception in Tkinter callback
2020-01-13 09:50:14,984 - root - ERROR - Exception in Tkinter callback
2020-01-13 09:50:14,984 - root - ERROR - Exception in Tkinter callback
2020-01-13 09:50:14,984 - root - ERROR - Exception in Tkinter callback
2020-01-13 09:50:14,984 - root - ERROR - Exception in Tkinter callback
2020-01-13 09:50:14,984 - root - ERROR - Exception in Tkinter callback
2020-01-13 09:50:14,984 - root - ERROR - Exception in Tkinter callback
2020-01-13 09:50:14,984 - root - ERROR - Exception in Tkinter callback
2020-01-13 09:50:14,984 - root - ERROR - Exception in Tkinter callback
2020-01-13 09:50:14,984 - root - ERROR - Exception in Tkinter callback
2020-01-13 09:50:14,984 - root - ERROR - 

2020-01-13 09:50:14,984 - root - ERROR - 

2020-01-13 09:50:14,984 - root - ERROR - 

2020-01-13 09:50:14,984 - root - ERROR - 

2020-01-13 09:50:14,984 - root - ERROR - 

2020-01-13 09:50:14,984 - root - ERROR - 

2020-01-13 09:50:14,984 - root - ERROR - 

2020-01-13 09:50:14,984 - root - ERROR - 

2020-01-13 09:50:14,984 - root - ERROR - 

2020-01-13 09:50:14,984 - root - ERROR - 

2020-01-13 09:50:14,984 - root - ERROR - 

2020-01-13 09:50:14,984 - root - ERROR - 

2020-01-13 09:50:14,984 - root - ERROR - 

2020-01-13 09:50:14,984 - root - ERROR - 

2020-01-13 09:50:14,984 - root - ERROR - Traceback (most recent call last):

2020-01-13 09:50:14,984 - root - ERROR - Traceback (most recent call last):

2020-01-13 09:50:14,984 - root - ERROR - Traceback (most recent call last):

2020-01-13 09:50:14,984 - root - ERROR - Traceback (most recent call last):

2020-01-13 09:50:14,984 - root - ERROR - Traceback (most recent call last):

2020-01-13 09:50:14,984 - root - ERROR - Traceback (most recent call last):

2020-01-13 09:50:14,984 - root - ERROR - Traceback (most recent call last):

2020-01-13 09:50:14,984 - root - ERROR - Traceback (most recent call last):

2020-01-13 09:50:14,984 - root - ERROR - Traceback (most recent call last):

2020-01-13 09:50:14,984 - root - ERROR - Traceback (most recent call last):

2020-01-13 09:50:14,984 - root - ERROR - Traceback (most recent call last):

2020-01-13 09:50:14,984 - root - ERROR - Traceback (most recent call last):

2020-01-13 09:50:14,984 - root - ERROR - Traceback (most recent call last):

2020-01-13 09:50:14,984 - root - ERROR - Traceback (most recent call last):

2020-01-13 09:50:14,984 - root - ERROR - 
2020-01-13 09:50:14,984 - root - ERROR - 
2020-01-13 09:50:14,984 - root - ERROR - 
2020-01-13 09:50:14,984 - root - ERROR - 
2020-01-13 09:50:14,984 - root - ERROR - 
2020-01-13 09:50:14,984 - root - ERROR - 
2020-01-13 09:50:14,984 - root - ERROR - 
2020-01-13 09:50:14,984 - root - ERROR - 
2020-01-13 09:50:14,984 - root - ERROR - 
2020-01-13 09:50:14,984 - root - ERROR - 
2020-01-13 09:50:14,984 - root - ERROR - 
2020-01-13 09:50:14,984 - root - ERROR - 
2020-01-13 09:50:14,984 - root - ERROR - 
2020-01-13 09:50:14,984 - root - ERROR - 
2020-01-13 09:50:14,984 - root - ERROR -   File "tkinter\__init__.py", line 1883, in __call__

2020-01-13 09:50:14,984 - root - ERROR -   File "tkinter\__init__.py", line 1883, in __call__

2020-01-13 09:50:14,984 - root - ERROR -   File "tkinter\__init__.py", line 1883, in __call__

2020-01-13 09:50:14,984 - root - ERROR -   File "tkinter\__init__.py", line 1883, in __call__

2020-01-13 09:50:14,984 - root - ERROR -   File "tkinter\__init__.py", line 1883, in __call__

2020-01-13 09:50:14,984 - root - ERROR -   File "tkinter\__init__.py", line 1883, in __call__

2020-01-13 09:50:14,984 - root - ERROR -   File "tkinter\__init__.py", line 1883, in __call__

2020-01-13 09:50:14,984 - root - ERROR -   File "tkinter\__init__.py", line 1883, in __call__

2020-01-13 09:50:14,984 - root - ERROR -   File "tkinter\__init__.py", line 1883, in __call__

2020-01-13 09:50:14,984 - root - ERROR -   File "tkinter\__init__.py", line 1883, in __call__

2020-01-13 09:50:14,984 - root - ERROR -   File "tkinter\__init__.py", line 1883, in __call__

2020-01-13 09:50:14,984 - root - ERROR -   File "tkinter\__init__.py", line 1883, in __call__

2020-01-13 09:50:14,984 - root - ERROR -   File "tkinter\__init__.py", line 1883, in __call__

2020-01-13 09:50:14,984 - root - ERROR -   File "tkinter\__init__.py", line 1883, in __call__

2020-01-13 09:50:14,984 - root - ERROR - 
2020-01-13 09:50:14,984 - root - ERROR - 
2020-01-13 09:50:14,984 - root - ERROR - 
2020-01-13 09:50:14,984 - root - ERROR - 
2020-01-13 09:50:14,984 - root - ERROR - 
2020-01-13 09:50:14,984 - root - ERROR - 
2020-01-13 09:50:14,984 - root - ERROR - 
2020-01-13 09:50:14,984 - root - ERROR - 
2020-01-13 09:50:14,984 - root - ERROR - 
2020-01-13 09:50:14,984 - root - ERROR - 
2020-01-13 09:50:14,984 - root - ERROR - 
2020-01-13 09:50:14,984 - root - ERROR - 
2020-01-13 09:50:14,984 - root - ERROR - 
2020-01-13 09:50:14,984 - root - ERROR - 
2020-01-13 09:50:14,984 - root - ERROR -   File "service_book.pyw", line 1302, in edit_scheduled_tasks

2020-01-13 09:50:14,984 - root - ERROR -   File "service_book.pyw", line 1302, in edit_scheduled_tasks

2020-01-13 09:50:14,984 - root - ERROR -   File "service_book.pyw", line 1302, in edit_scheduled_tasks

2020-01-13 09:50:14,984 - root - ERROR -   File "service_book.pyw", line 1302, in edit_scheduled_tasks

2020-01-13 09:50:14,984 - root - ERROR -   File "service_book.pyw", line 1302, in edit_scheduled_tasks

2020-01-13 09:50:14,984 - root - ERROR -   File "service_book.pyw", line 1302, in edit_scheduled_tasks

2020-01-13 09:50:14,984 - root - ERROR -   File "service_book.pyw", line 1302, in edit_scheduled_tasks

2020-01-13 09:50:14,984 - root - ERROR -   File "service_book.pyw", line 1302, in edit_scheduled_tasks

2020-01-13 09:50:14,984 - root - ERROR -   File "service_book.pyw", line 1302, in edit_scheduled_tasks

2020-01-13 09:50:14,984 - root - ERROR -   File "service_book.pyw", line 1302, in edit_scheduled_tasks

2020-01-13 09:50:14,984 - root - ERROR -   File "service_book.pyw", line 1302, in edit_scheduled_tasks

2020-01-13 09:50:14,984 - root - ERROR -   File "service_book.pyw", line 1302, in edit_scheduled_tasks

2020-01-13 09:50:14,984 - root - ERROR -   File "service_book.pyw", line 1302, in edit_scheduled_tasks

2020-01-13 09:50:14,984 - root - ERROR -   File "service_book.pyw", line 1302, in edit_scheduled_tasks

2020-01-13 09:50:14,984 - root - ERROR - 
2020-01-13 09:50:14,984 - root - ERROR - 
2020-01-13 09:50:14,984 - root - ERROR - 
2020-01-13 09:50:14,984 - root - ERROR - 
2020-01-13 09:50:14,984 - root - ERROR - 
2020-01-13 09:50:14,984 - root - ERROR - 
2020-01-13 09:50:14,984 - root - ERROR - 
2020-01-13 09:50:14,984 - root - ERROR - 
2020-01-13 09:50:14,984 - root - ERROR - 
2020-01-13 09:50:14,984 - root - ERROR - 
2020-01-13 09:50:14,984 - root - ERROR - 
2020-01-13 09:50:14,984 - root - ERROR - 
2020-01-13 09:50:14,984 - root - ERROR - 
2020-01-13 09:50:14,984 - root - ERROR - 
2020-01-13 09:50:14,984 - root - ERROR -   File "edit_task.py", line 97, in create_edit_task_window

2020-01-13 09:50:14,984 - root - ERROR -   File "edit_task.py", line 97, in create_edit_task_window

2020-01-13 09:50:14,984 - root - ERROR -   File "edit_task.py", line 97, in create_edit_task_window

2020-01-13 09:50:14,984 - root - ERROR -   File "edit_task.py", line 97, in create_edit_task_window

2020-01-13 09:50:14,984 - root - ERROR -   File "edit_task.py", line 97, in create_edit_task_window

2020-01-13 09:50:14,984 - root - ERROR -   File "edit_task.py", line 97, in create_edit_task_window

2020-01-13 09:50:14,984 - root - ERROR -   File "edit_task.py", line 97, in create_edit_task_window

2020-01-13 09:50:14,984 - root - ERROR -   File "edit_task.py", line 97, in create_edit_task_window

2020-01-13 09:50:14,984 - root - ERROR -   File "edit_task.py", line 97, in create_edit_task_window

2020-01-13 09:50:14,984 - root - ERROR -   File "edit_task.py", line 97, in create_edit_task_window

2020-01-13 09:50:14,984 - root - ERROR -   File "edit_task.py", line 97, in create_edit_task_window

2020-01-13 09:50:14,984 - root - ERROR -   File "edit_task.py", line 97, in create_edit_task_window

2020-01-13 09:50:14,984 - root - ERROR -   File "edit_task.py", line 97, in create_edit_task_window

2020-01-13 09:50:14,984 - root - ERROR -   File "edit_task.py", line 97, in create_edit_task_window

2020-01-13 09:50:14,984 - root - ERROR - 
2020-01-13 09:50:14,984 - root - ERROR - 
2020-01-13 09:50:14,984 - root - ERROR - 
2020-01-13 09:50:14,984 - root - ERROR - 
2020-01-13 09:50:14,984 - root - ERROR - 
2020-01-13 09:50:14,984 - root - ERROR - 
2020-01-13 09:50:14,984 - root - ERROR - 
2020-01-13 09:50:14,984 - root - ERROR - 
2020-01-13 09:50:14,984 - root - ERROR - 
2020-01-13 09:50:14,984 - root - ERROR - 
2020-01-13 09:50:14,984 - root - ERROR - 
2020-01-13 09:50:14,984 - root - ERROR - 
2020-01-13 09:50:14,984 - root - ERROR - 
2020-01-13 09:50:14,984 - root - ERROR - 
2020-01-13 09:50:14,984 - root - ERROR -   File "edit_task.py", line 662, in __init__

2020-01-13 09:50:14,984 - root - ERROR -   File "edit_task.py", line 662, in __init__

2020-01-13 09:50:14,984 - root - ERROR -   File "edit_task.py", line 662, in __init__

2020-01-13 09:50:14,984 - root - ERROR -   File "edit_task.py", line 662, in __init__

2020-01-13 09:50:14,984 - root - ERROR -   File "edit_task.py", line 662, in __init__

2020-01-13 09:50:14,984 - root - ERROR -   File "edit_task.py", line 662, in __init__

2020-01-13 09:50:14,984 - root - ERROR -   File "edit_task.py", line 662, in __init__

2020-01-13 09:50:14,984 - root - ERROR -   File "edit_task.py", line 662, in __init__

2020-01-13 09:50:14,984 - root - ERROR -   File "edit_task.py", line 662, in __init__

2020-01-13 09:50:14,984 - root - ERROR -   File "edit_task.py", line 662, in __init__

2020-01-13 09:50:14,984 - root - ERROR -   File "edit_task.py", line 662, in __init__

2020-01-13 09:50:14,984 - root - ERROR -   File "edit_task.py", line 662, in __init__

2020-01-13 09:50:14,984 - root - ERROR -   File "edit_task.py", line 662, in __init__

2020-01-13 09:50:14,984 - root - ERROR -   File "edit_task.py", line 662, in __init__

2020-01-13 09:50:14,984 - root - ERROR - 
2020-01-13 09:50:14,984 - root - ERROR - 
2020-01-13 09:50:14,984 - root - ERROR - 
2020-01-13 09:50:14,984 - root - ERROR - 
2020-01-13 09:50:14,984 - root - ERROR - 
2020-01-13 09:50:14,984 - root - ERROR - 
2020-01-13 09:50:14,984 - root - ERROR - 
2020-01-13 09:50:14,984 - root - ERROR - 
2020-01-13 09:50:14,984 - root - ERROR - 
2020-01-13 09:50:14,984 - root - ERROR - 
2020-01-13 09:50:14,984 - root - ERROR - 
2020-01-13 09:50:14,984 - root - ERROR - 
2020-01-13 09:50:14,984 - root - ERROR - 
2020-01-13 09:50:14,984 - root - ERROR - 
2020-01-13 09:50:14,984 - root - ERROR -   File "tkinter\__init__.py", line 4061, in __init__

2020-01-13 09:50:14,984 - root - ERROR -   File "tkinter\__init__.py", line 4061, in __init__

2020-01-13 09:50:14,984 - root - ERROR -   File "tkinter\__init__.py", line 4061, in __init__

2020-01-13 09:50:14,984 - root - ERROR -   File "tkinter\__init__.py", line 4061, in __init__

2020-01-13 09:50:14,984 - root - ERROR -   File "tkinter\__init__.py", line 4061, in __init__

2020-01-13 09:50:14,984 - root - ERROR -   File "tkinter\__init__.py", line 4061, in __init__

2020-01-13 09:50:14,984 - root - ERROR -   File "tkinter\__init__.py", line 4061, in __init__

2020-01-13 09:50:14,984 - root - ERROR -   File "tkinter\__init__.py", line 4061, in __init__

2020-01-13 09:50:14,984 - root - ERROR -   File "tkinter\__init__.py", line 4061, in __init__

2020-01-13 09:50:14,984 - root - ERROR -   File "tkinter\__init__.py", line 4061, in __init__

2020-01-13 09:50:14,984 - root - ERROR -   File "tkinter\__init__.py", line 4061, in __init__

2020-01-13 09:50:14,984 - root - ERROR -   File "tkinter\__init__.py", line 4061, in __init__

2020-01-13 09:50:14,984 - root - ERROR -   File "tkinter\__init__.py", line 4061, in __init__

2020-01-13 09:50:14,984 - root - ERROR -   File "tkinter\__init__.py", line 4061, in __init__

2020-01-13 09:50:14,984 - root - ERROR - 
2020-01-13 09:50:14,984 - root - ERROR - 
2020-01-13 09:50:14,984 - root - ERROR - 
2020-01-13 09:50:14,984 - root - ERROR - 
2020-01-13 09:50:14,984 - root - ERROR - 
2020-01-13 09:50:14,984 - root - ERROR - 
2020-01-13 09:50:14,984 - root - ERROR - 
2020-01-13 09:50:14,984 - root - ERROR - 
2020-01-13 09:50:14,984 - root - ERROR - 
2020-01-13 09:50:14,984 - root - ERROR - 
2020-01-13 09:50:14,984 - root - ERROR - 
2020-01-13 09:50:14,984 - root - ERROR - 
2020-01-13 09:50:14,984 - root - ERROR - 
2020-01-13 09:50:14,984 - root - ERROR - 
2020-01-13 09:50:14,984 - root - ERROR -   File "tkinter\__init__.py", line 4006, in __init__

2020-01-13 09:50:14,984 - root - ERROR -   File "tkinter\__init__.py", line 4006, in __init__

2020-01-13 09:50:14,984 - root - ERROR -   File "tkinter\__init__.py", line 4006, in __init__

2020-01-13 09:50:14,984 - root - ERROR -   File "tkinter\__init__.py", line 4006, in __init__

2020-01-13 09:50:14,984 - root - ERROR -   File "tkinter\__init__.py", line 4006, in __init__

2020-01-13 09:50:14,984 - root - ERROR -   File "tkinter\__init__.py", line 4006, in __init__

2020-01-13 09:50:14,984 - root - ERROR -   File "tkinter\__init__.py", line 4006, in __init__

2020-01-13 09:50:14,984 - root - ERROR -   File "tkinter\__init__.py", line 4006, in __init__

2020-01-13 09:50:14,984 - root - ERROR -   File "tkinter\__init__.py", line 4006, in __init__

2020-01-13 09:50:14,984 - root - ERROR -   File "tkinter\__init__.py", line 4006, in __init__

2020-01-13 09:50:14,984 - root - ERROR -   File "tkinter\__init__.py", line 4006, in __init__

2020-01-13 09:50:14,984 - root - ERROR -   File "tkinter\__init__.py", line 4006, in __init__

2020-01-13 09:50:14,984 - root - ERROR -   File "tkinter\__init__.py", line 4006, in __init__

2020-01-13 09:50:14,984 - root - ERROR -   File "tkinter\__init__.py", line 4006, in __init__

2020-01-13 09:50:14,984 - root - ERROR - 
2020-01-13 09:50:14,984 - root - ERROR - 
2020-01-13 09:50:14,984 - root - ERROR - 
2020-01-13 09:50:14,984 - root - ERROR - 
2020-01-13 09:50:14,984 - root - ERROR - 
2020-01-13 09:50:14,984 - root - ERROR - 
2020-01-13 09:50:14,984 - root - ERROR - 
2020-01-13 09:50:14,984 - root - ERROR - 
2020-01-13 09:50:14,984 - root - ERROR - 
2020-01-13 09:50:14,984 - root - ERROR - 
2020-01-13 09:50:14,984 - root - ERROR - 
2020-01-13 09:50:14,984 - root - ERROR - 
2020-01-13 09:50:14,984 - root - ERROR - 
2020-01-13 09:50:14,984 - root - ERROR - 
2020-01-13 09:50:14,984 - root - ERROR - _tkinter.TclError: couldn't open "icons/view_files.png": no such file or directory

2020-01-13 09:50:14,984 - root - ERROR - _tkinter.TclError: couldn't open "icons/view_files.png": no such file or directory

2020-01-13 09:50:14,984 - root - ERROR - _tkinter.TclError: couldn't open "icons/view_files.png": no such file or directory

2020-01-13 09:50:14,984 - root - ERROR - _tkinter.TclError: couldn't open "icons/view_files.png": no such file or directory

2020-01-13 09:50:14,984 - root - ERROR - _tkinter.TclError: couldn't open "icons/view_files.png": no such file or directory

2020-01-13 09:50:14,984 - root - ERROR - _tkinter.TclError: couldn't open "icons/view_files.png": no such file or directory

2020-01-13 09:50:14,984 - root - ERROR - _tkinter.TclError: couldn't open "icons/view_files.png": no such file or directory

2020-01-13 09:50:14,984 - root - ERROR - _tkinter.TclError: couldn't open "icons/view_files.png": no such file or directory

2020-01-13 09:50:14,984 - root - ERROR - _tkinter.TclError: couldn't open "icons/view_files.png": no such file or directory

2020-01-13 09:50:14,984 - root - ERROR - _tkinter.TclError: couldn't open "icons/view_files.png": no such file or directory

2020-01-13 09:50:14,984 - root - ERROR - _tkinter.TclError: couldn't open "icons/view_files.png": no such file or directory

2020-01-13 09:50:14,984 - root - ERROR - _tkinter.TclError: couldn't open "icons/view_files.png": no such file or directory

2020-01-13 09:50:14,984 - root - ERROR - _tkinter.TclError: couldn't open "icons/view_files.png": no such file or directory

2020-01-13 09:50:14,984 - root - ERROR - _tkinter.TclError: couldn't open "icons/view_files.png": no such file or directory

2020-01-13 09:50:14,984 - root - ERROR - 
2020-01-13 09:50:14,984 - root - ERROR - 
2020-01-13 09:50:14,984 - root - ERROR - 
2020-01-13 09:50:14,984 - root - ERROR - 
2020-01-13 09:50:14,984 - root - ERROR - 
2020-01-13 09:50:14,984 - root - ERROR - 
2020-01-13 09:50:14,984 - root - ERROR - 
2020-01-13 09:50:14,984 - root - ERROR - 
2020-01-13 09:50:14,984 - root - ERROR - 
2020-01-13 09:50:14,984 - root - ERROR - 
2020-01-13 09:50:14,984 - root - ERROR - 
2020-01-13 09:50:14,984 - root - ERROR - 
2020-01-13 09:50:14,984 - root - ERROR - 
2020-01-13 09:50:14,984 - root - ERROR - 
2020-01-13 09:50:27,276 - root - ERROR - Exception in Tkinter callback
2020-01-13 09:50:27,276 - root - ERROR - Exception in Tkinter callback
2020-01-13 09:50:27,276 - root - ERROR - Exception in Tkinter callback
2020-01-13 09:50:27,276 - root - ERROR - Exception in Tkinter callback
2020-01-13 09:50:27,276 - root - ERROR - Exception in Tkinter callback
2020-01-13 09:50:27,276 - root - ERROR - Exception in Tkinter callback
2020-01-13 09:50:27,276 - root - ERROR - Exception in Tkinter callback
2020-01-13 09:50:27,276 - root - ERROR - Exception in Tkinter callback
2020-01-13 09:50:27,276 - root - ERROR - Exception in Tkinter callback
2020-01-13 09:50:27,276 - root - ERROR - Exception in Tkinter callback
2020-01-13 09:50:27,276 - root - ERROR - Exception in Tkinter callback
2020-01-13 09:50:27,276 - root - ERROR - Exception in Tkinter callback
2020-01-13 09:50:27,276 - root - ERROR - Exception in Tkinter callback
2020-01-13 09:50:27,276 - root - ERROR - Exception in Tkinter callback
2020-01-13 09:50:27,276 - root - ERROR - 

2020-01-13 09:50:27,276 - root - ERROR - 

2020-01-13 09:50:27,276 - root - ERROR - 

2020-01-13 09:50:27,276 - root - ERROR - 

2020-01-13 09:50:27,276 - root - ERROR - 

2020-01-13 09:50:27,276 - root - ERROR - 

2020-01-13 09:50:27,276 - root - ERROR - 

2020-01-13 09:50:27,276 - root - ERROR - 

2020-01-13 09:50:27,276 - root - ERROR - 

2020-01-13 09:50:27,276 - root - ERROR - 

2020-01-13 09:50:27,276 - root - ERROR - 

2020-01-13 09:50:27,276 - root - ERROR - 

2020-01-13 09:50:27,276 - root - ERROR - 

2020-01-13 09:50:27,276 - root - ERROR - 

2020-01-13 09:50:27,276 - root - ERROR - Traceback (most recent call last):

2020-01-13 09:50:27,276 - root - ERROR - Traceback (most recent call last):

2020-01-13 09:50:27,276 - root - ERROR - Traceback (most recent call last):

2020-01-13 09:50:27,276 - root - ERROR - Traceback (most recent call last):

2020-01-13 09:50:27,276 - root - ERROR - Traceback (most recent call last):

2020-01-13 09:50:27,276 - root - ERROR - Traceback (most recent call last):

2020-01-13 09:50:27,276 - root - ERROR - Traceback (most recent call last):

2020-01-13 09:50:27,276 - root - ERROR - Traceback (most recent call last):

2020-01-13 09:50:27,276 - root - ERROR - Traceback (most recent call last):

2020-01-13 09:50:27,276 - root - ERROR - Traceback (most recent call last):

2020-01-13 09:50:27,276 - root - ERROR - Traceback (most recent call last):

2020-01-13 09:50:27,276 - root - ERROR - Traceback (most recent call last):

2020-01-13 09:50:27,276 - root - ERROR - Traceback (most recent call last):

2020-01-13 09:50:27,276 - root - ERROR - Traceback (most recent call last):

2020-01-13 09:50:27,276 - root - ERROR - 
2020-01-13 09:50:27,276 - root - ERROR - 
2020-01-13 09:50:27,276 - root - ERROR - 
2020-01-13 09:50:27,276 - root - ERROR - 
2020-01-13 09:50:27,276 - root - ERROR - 
2020-01-13 09:50:27,276 - root - ERROR - 
2020-01-13 09:50:27,276 - root - ERROR - 
2020-01-13 09:50:27,276 - root - ERROR - 
2020-01-13 09:50:27,276 - root - ERROR - 
2020-01-13 09:50:27,276 - root - ERROR - 
2020-01-13 09:50:27,276 - root - ERROR - 
2020-01-13 09:50:27,276 - root - ERROR - 
2020-01-13 09:50:27,276 - root - ERROR - 
2020-01-13 09:50:27,276 - root - ERROR - 
2020-01-13 09:50:27,276 - root - ERROR -   File "tkinter\__init__.py", line 1883, in __call__

2020-01-13 09:50:27,276 - root - ERROR -   File "tkinter\__init__.py", line 1883, in __call__

2020-01-13 09:50:27,276 - root - ERROR -   File "tkinter\__init__.py", line 1883, in __call__

2020-01-13 09:50:27,276 - root - ERROR -   File "tkinter\__init__.py", line 1883, in __call__

2020-01-13 09:50:27,276 - root - ERROR -   File "tkinter\__init__.py", line 1883, in __call__

2020-01-13 09:50:27,276 - root - ERROR -   File "tkinter\__init__.py", line 1883, in __call__

2020-01-13 09:50:27,276 - root - ERROR -   File "tkinter\__init__.py", line 1883, in __call__

2020-01-13 09:50:27,276 - root - ERROR -   File "tkinter\__init__.py", line 1883, in __call__

2020-01-13 09:50:27,276 - root - ERROR -   File "tkinter\__init__.py", line 1883, in __call__

2020-01-13 09:50:27,276 - root - ERROR -   File "tkinter\__init__.py", line 1883, in __call__

2020-01-13 09:50:27,276 - root - ERROR -   File "tkinter\__init__.py", line 1883, in __call__

2020-01-13 09:50:27,276 - root - ERROR -   File "tkinter\__init__.py", line 1883, in __call__

2020-01-13 09:50:27,276 - root - ERROR -   File "tkinter\__init__.py", line 1883, in __call__

2020-01-13 09:50:27,276 - root - ERROR -   File "tkinter\__init__.py", line 1883, in __call__

2020-01-13 09:50:27,276 - root - ERROR - 
2020-01-13 09:50:27,276 - root - ERROR - 
2020-01-13 09:50:27,276 - root - ERROR - 
2020-01-13 09:50:27,276 - root - ERROR - 
2020-01-13 09:50:27,276 - root - ERROR - 
2020-01-13 09:50:27,276 - root - ERROR - 
2020-01-13 09:50:27,276 - root - ERROR - 
2020-01-13 09:50:27,276 - root - ERROR - 
2020-01-13 09:50:27,276 - root - ERROR - 
2020-01-13 09:50:27,276 - root - ERROR - 
2020-01-13 09:50:27,276 - root - ERROR - 
2020-01-13 09:50:27,276 - root - ERROR - 
2020-01-13 09:50:27,276 - root - ERROR - 
2020-01-13 09:50:27,276 - root - ERROR - 
2020-01-13 09:50:27,276 - root - ERROR -   File "service_book.pyw", line 1302, in edit_scheduled_tasks

2020-01-13 09:50:27,276 - root - ERROR -   File "service_book.pyw", line 1302, in edit_scheduled_tasks

2020-01-13 09:50:27,276 - root - ERROR -   File "service_book.pyw", line 1302, in edit_scheduled_tasks

2020-01-13 09:50:27,276 - root - ERROR -   File "service_book.pyw", line 1302, in edit_scheduled_tasks

2020-01-13 09:50:27,276 - root - ERROR -   File "service_book.pyw", line 1302, in edit_scheduled_tasks

2020-01-13 09:50:27,276 - root - ERROR -   File "service_book.pyw", line 1302, in edit_scheduled_tasks

2020-01-13 09:50:27,276 - root - ERROR -   File "service_book.pyw", line 1302, in edit_scheduled_tasks

2020-01-13 09:50:27,276 - root - ERROR -   File "service_book.pyw", line 1302, in edit_scheduled_tasks

2020-01-13 09:50:27,276 - root - ERROR -   File "service_book.pyw", line 1302, in edit_scheduled_tasks

2020-01-13 09:50:27,276 - root - ERROR -   File "service_book.pyw", line 1302, in edit_scheduled_tasks

2020-01-13 09:50:27,276 - root - ERROR -   File "service_book.pyw", line 1302, in edit_scheduled_tasks

2020-01-13 09:50:27,276 - root - ERROR -   File "service_book.pyw", line 1302, in edit_scheduled_tasks

2020-01-13 09:50:27,276 - root - ERROR -   File "service_book.pyw", line 1302, in edit_scheduled_tasks

2020-01-13 09:50:27,276 - root - ERROR -   File "service_book.pyw", line 1302, in edit_scheduled_tasks

2020-01-13 09:50:27,276 - root - ERROR - 
2020-01-13 09:50:27,276 - root - ERROR - 
2020-01-13 09:50:27,276 - root - ERROR - 
2020-01-13 09:50:27,276 - root - ERROR - 
2020-01-13 09:50:27,276 - root - ERROR - 
2020-01-13 09:50:27,276 - root - ERROR - 
2020-01-13 09:50:27,276 - root - ERROR - 
2020-01-13 09:50:27,276 - root - ERROR - 
2020-01-13 09:50:27,276 - root - ERROR - 
2020-01-13 09:50:27,276 - root - ERROR - 
2020-01-13 09:50:27,276 - root - ERROR - 
2020-01-13 09:50:27,276 - root - ERROR - 
2020-01-13 09:50:27,276 - root - ERROR - 
2020-01-13 09:50:27,276 - root - ERROR - 
2020-01-13 09:50:27,276 - root - ERROR -   File "edit_task.py", line 97, in create_edit_task_window

2020-01-13 09:50:27,276 - root - ERROR -   File "edit_task.py", line 97, in create_edit_task_window

2020-01-13 09:50:27,276 - root - ERROR -   File "edit_task.py", line 97, in create_edit_task_window

2020-01-13 09:50:27,276 - root - ERROR -   File "edit_task.py", line 97, in create_edit_task_window

2020-01-13 09:50:27,276 - root - ERROR -   File "edit_task.py", line 97, in create_edit_task_window

2020-01-13 09:50:27,276 - root - ERROR -   File "edit_task.py", line 97, in create_edit_task_window

2020-01-13 09:50:27,276 - root - ERROR -   File "edit_task.py", line 97, in create_edit_task_window

2020-01-13 09:50:27,276 - root - ERROR -   File "edit_task.py", line 97, in create_edit_task_window

2020-01-13 09:50:27,276 - root - ERROR -   File "edit_task.py", line 97, in create_edit_task_window

2020-01-13 09:50:27,276 - root - ERROR -   File "edit_task.py", line 97, in create_edit_task_window

2020-01-13 09:50:27,276 - root - ERROR -   File "edit_task.py", line 97, in create_edit_task_window

2020-01-13 09:50:27,276 - root - ERROR -   File "edit_task.py", line 97, in create_edit_task_window

2020-01-13 09:50:27,276 - root - ERROR -   File "edit_task.py", line 97, in create_edit_task_window

2020-01-13 09:50:27,276 - root - ERROR -   File "edit_task.py", line 97, in create_edit_task_window

2020-01-13 09:50:27,276 - root - ERROR - 
2020-01-13 09:50:27,276 - root - ERROR - 
2020-01-13 09:50:27,276 - root - ERROR - 
2020-01-13 09:50:27,276 - root - ERROR - 
2020-01-13 09:50:27,276 - root - ERROR - 
2020-01-13 09:50:27,276 - root - ERROR - 
2020-01-13 09:50:27,276 - root - ERROR - 
2020-01-13 09:50:27,276 - root - ERROR - 
2020-01-13 09:50:27,276 - root - ERROR - 
2020-01-13 09:50:27,276 - root - ERROR - 
2020-01-13 09:50:27,276 - root - ERROR - 
2020-01-13 09:50:27,276 - root - ERROR - 
2020-01-13 09:50:27,276 - root - ERROR - 
2020-01-13 09:50:27,276 - root - ERROR - 
2020-01-13 09:50:27,276 - root - ERROR -   File "edit_task.py", line 662, in __init__

2020-01-13 09:50:27,276 - root - ERROR -   File "edit_task.py", line 662, in __init__

2020-01-13 09:50:27,276 - root - ERROR -   File "edit_task.py", line 662, in __init__

2020-01-13 09:50:27,276 - root - ERROR -   File "edit_task.py", line 662, in __init__

2020-01-13 09:50:27,276 - root - ERROR -   File "edit_task.py", line 662, in __init__

2020-01-13 09:50:27,276 - root - ERROR -   File "edit_task.py", line 662, in __init__

2020-01-13 09:50:27,276 - root - ERROR -   File "edit_task.py", line 662, in __init__

2020-01-13 09:50:27,276 - root - ERROR -   File "edit_task.py", line 662, in __init__

2020-01-13 09:50:27,276 - root - ERROR -   File "edit_task.py", line 662, in __init__

2020-01-13 09:50:27,276 - root - ERROR -   File "edit_task.py", line 662, in __init__

2020-01-13 09:50:27,276 - root - ERROR -   File "edit_task.py", line 662, in __init__

2020-01-13 09:50:27,276 - root - ERROR -   File "edit_task.py", line 662, in __init__

2020-01-13 09:50:27,276 - root - ERROR -   File "edit_task.py", line 662, in __init__

2020-01-13 09:50:27,276 - root - ERROR -   File "edit_task.py", line 662, in __init__

2020-01-13 09:50:27,276 - root - ERROR - 
2020-01-13 09:50:27,276 - root - ERROR - 
2020-01-13 09:50:27,276 - root - ERROR - 
2020-01-13 09:50:27,276 - root - ERROR - 
2020-01-13 09:50:27,276 - root - ERROR - 
2020-01-13 09:50:27,276 - root - ERROR - 
2020-01-13 09:50:27,276 - root - ERROR - 
2020-01-13 09:50:27,276 - root - ERROR - 
2020-01-13 09:50:27,276 - root - ERROR - 
2020-01-13 09:50:27,276 - root - ERROR - 
2020-01-13 09:50:27,276 - root - ERROR - 
2020-01-13 09:50:27,276 - root - ERROR - 
2020-01-13 09:50:27,276 - root - ERROR - 
2020-01-13 09:50:27,276 - root - ERROR - 
2020-01-13 09:50:27,276 - root - ERROR -   File "tkinter\__init__.py", line 4061, in __init__

2020-01-13 09:50:27,276 - root - ERROR -   File "tkinter\__init__.py", line 4061, in __init__

2020-01-13 09:50:27,276 - root - ERROR -   File "tkinter\__init__.py", line 4061, in __init__

2020-01-13 09:50:27,276 - root - ERROR -   File "tkinter\__init__.py", line 4061, in __init__

2020-01-13 09:50:27,276 - root - ERROR -   File "tkinter\__init__.py", line 4061, in __init__

2020-01-13 09:50:27,276 - root - ERROR -   File "tkinter\__init__.py", line 4061, in __init__

2020-01-13 09:50:27,276 - root - ERROR -   File "tkinter\__init__.py", line 4061, in __init__

2020-01-13 09:50:27,276 - root - ERROR -   File "tkinter\__init__.py", line 4061, in __init__

2020-01-13 09:50:27,276 - root - ERROR -   File "tkinter\__init__.py", line 4061, in __init__

2020-01-13 09:50:27,276 - root - ERROR -   File "tkinter\__init__.py", line 4061, in __init__

2020-01-13 09:50:27,276 - root - ERROR -   File "tkinter\__init__.py", line 4061, in __init__

2020-01-13 09:50:27,276 - root - ERROR -   File "tkinter\__init__.py", line 4061, in __init__

2020-01-13 09:50:27,276 - root - ERROR -   File "tkinter\__init__.py", line 4061, in __init__

2020-01-13 09:50:27,276 - root - ERROR -   File "tkinter\__init__.py", line 4061, in __init__

2020-01-13 09:50:27,276 - root - ERROR - 
2020-01-13 09:50:27,276 - root - ERROR - 
2020-01-13 09:50:27,276 - root - ERROR - 
2020-01-13 09:50:27,276 - root - ERROR - 
2020-01-13 09:50:27,276 - root - ERROR - 
2020-01-13 09:50:27,276 - root - ERROR - 
2020-01-13 09:50:27,276 - root - ERROR - 
2020-01-13 09:50:27,276 - root - ERROR - 
2020-01-13 09:50:27,276 - root - ERROR - 
2020-01-13 09:50:27,276 - root - ERROR - 
2020-01-13 09:50:27,276 - root - ERROR - 
2020-01-13 09:50:27,276 - root - ERROR - 
2020-01-13 09:50:27,276 - root - ERROR - 
2020-01-13 09:50:27,276 - root - ERROR - 
2020-01-13 09:50:27,276 - root - ERROR -   File "tkinter\__init__.py", line 4006, in __init__

2020-01-13 09:50:27,276 - root - ERROR -   File "tkinter\__init__.py", line 4006, in __init__

2020-01-13 09:50:27,276 - root - ERROR -   File "tkinter\__init__.py", line 4006, in __init__

2020-01-13 09:50:27,276 - root - ERROR -   File "tkinter\__init__.py", line 4006, in __init__

2020-01-13 09:50:27,276 - root - ERROR -   File "tkinter\__init__.py", line 4006, in __init__

2020-01-13 09:50:27,276 - root - ERROR -   File "tkinter\__init__.py", line 4006, in __init__

2020-01-13 09:50:27,276 - root - ERROR -   File "tkinter\__init__.py", line 4006, in __init__

2020-01-13 09:50:27,276 - root - ERROR -   File "tkinter\__init__.py", line 4006, in __init__

2020-01-13 09:50:27,276 - root - ERROR -   File "tkinter\__init__.py", line 4006, in __init__

2020-01-13 09:50:27,276 - root - ERROR -   File "tkinter\__init__.py", line 4006, in __init__

2020-01-13 09:50:27,276 - root - ERROR -   File "tkinter\__init__.py", line 4006, in __init__

2020-01-13 09:50:27,276 - root - ERROR -   File "tkinter\__init__.py", line 4006, in __init__

2020-01-13 09:50:27,276 - root - ERROR -   File "tkinter\__init__.py", line 4006, in __init__

2020-01-13 09:50:27,276 - root - ERROR -   File "tkinter\__init__.py", line 4006, in __init__

2020-01-13 09:50:27,276 - root - ERROR - 
2020-01-13 09:50:27,276 - root - ERROR - 
2020-01-13 09:50:27,276 - root - ERROR - 
2020-01-13 09:50:27,276 - root - ERROR - 
2020-01-13 09:50:27,276 - root - ERROR - 
2020-01-13 09:50:27,276 - root - ERROR - 
2020-01-13 09:50:27,276 - root - ERROR - 
2020-01-13 09:50:27,276 - root - ERROR - 
2020-01-13 09:50:27,276 - root - ERROR - 
2020-01-13 09:50:27,276 - root - ERROR - 
2020-01-13 09:50:27,276 - root - ERROR - 
2020-01-13 09:50:27,276 - root - ERROR - 
2020-01-13 09:50:27,276 - root - ERROR - 
2020-01-13 09:50:27,276 - root - ERROR - 
2020-01-13 09:50:27,276 - root - ERROR - _tkinter.TclError: couldn't open "icons/view_files.png": no such file or directory

2020-01-13 09:50:27,276 - root - ERROR - _tkinter.TclError: couldn't open "icons/view_files.png": no such file or directory

2020-01-13 09:50:27,276 - root - ERROR - _tkinter.TclError: couldn't open "icons/view_files.png": no such file or directory

2020-01-13 09:50:27,276 - root - ERROR - _tkinter.TclError: couldn't open "icons/view_files.png": no such file or directory

2020-01-13 09:50:27,276 - root - ERROR - _tkinter.TclError: couldn't open "icons/view_files.png": no such file or directory

2020-01-13 09:50:27,276 - root - ERROR - _tkinter.TclError: couldn't open "icons/view_files.png": no such file or directory

2020-01-13 09:50:27,276 - root - ERROR - _tkinter.TclError: couldn't open "icons/view_files.png": no such file or directory

2020-01-13 09:50:27,276 - root - ERROR - _tkinter.TclError: couldn't open "icons/view_files.png": no such file or directory

2020-01-13 09:50:27,276 - root - ERROR - _tkinter.TclError: couldn't open "icons/view_files.png": no such file or directory

2020-01-13 09:50:27,276 - root - ERROR - _tkinter.TclError: couldn't open "icons/view_files.png": no such file or directory

2020-01-13 09:50:27,276 - root - ERROR - _tkinter.TclError: couldn't open "icons/view_files.png": no such file or directory

2020-01-13 09:50:27,276 - root - ERROR - _tkinter.TclError: couldn't open "icons/view_files.png": no such file or directory

2020-01-13 09:50:27,276 - root - ERROR - _tkinter.TclError: couldn't open "icons/view_files.png": no such file or directory

2020-01-13 09:50:27,276 - root - ERROR - _tkinter.TclError: couldn't open "icons/view_files.png": no such file or directory

2020-01-13 09:50:27,276 - root - ERROR - 
2020-01-13 09:50:27,276 - root - ERROR - 
2020-01-13 09:50:27,276 - root - ERROR - 
2020-01-13 09:50:27,276 - root - ERROR - 
2020-01-13 09:50:27,276 - root - ERROR - 
2020-01-13 09:50:27,276 - root - ERROR - 
2020-01-13 09:50:27,276 - root - ERROR - 
2020-01-13 09:50:27,276 - root - ERROR - 
2020-01-13 09:50:27,276 - root - ERROR - 
2020-01-13 09:50:27,276 - root - ERROR - 
2020-01-13 09:50:27,276 - root - ERROR - 
2020-01-13 09:50:27,276 - root - ERROR - 
2020-01-13 09:50:27,276 - root - ERROR - 
2020-01-13 09:50:27,276 - root - ERROR - 
2020-01-13 09:50:31,535 - root - ERROR - Exception in Tkinter callback
2020-01-13 09:50:31,535 - root - ERROR - Exception in Tkinter callback
2020-01-13 09:50:31,535 - root - ERROR - Exception in Tkinter callback
2020-01-13 09:50:31,535 - root - ERROR - Exception in Tkinter callback
2020-01-13 09:50:31,535 - root - ERROR - Exception in Tkinter callback
2020-01-13 09:50:31,535 - root - ERROR - Exception in Tkinter callback
2020-01-13 09:50:31,535 - root - ERROR - Exception in Tkinter callback
2020-01-13 09:50:31,535 - root - ERROR - Exception in Tkinter callback
2020-01-13 09:50:31,535 - root - ERROR - Exception in Tkinter callback
2020-01-13 09:50:31,535 - root - ERROR - Exception in Tkinter callback
2020-01-13 09:50:31,535 - root - ERROR - Exception in Tkinter callback
2020-01-13 09:50:31,535 - root - ERROR - Exception in Tkinter callback
2020-01-13 09:50:31,535 - root - ERROR - Exception in Tkinter callback
2020-01-13 09:50:31,535 - root - ERROR - Exception in Tkinter callback
2020-01-13 09:50:31,535 - root - ERROR - 

2020-01-13 09:50:31,535 - root - ERROR - 

2020-01-13 09:50:31,535 - root - ERROR - 

2020-01-13 09:50:31,535 - root - ERROR - 

2020-01-13 09:50:31,535 - root - ERROR - 

2020-01-13 09:50:31,535 - root - ERROR - 

2020-01-13 09:50:31,535 - root - ERROR - 

2020-01-13 09:50:31,535 - root - ERROR - 

2020-01-13 09:50:31,535 - root - ERROR - 

2020-01-13 09:50:31,535 - root - ERROR - 

2020-01-13 09:50:31,535 - root - ERROR - 

2020-01-13 09:50:31,535 - root - ERROR - 

2020-01-13 09:50:31,535 - root - ERROR - 

2020-01-13 09:50:31,535 - root - ERROR - 

2020-01-13 09:50:31,535 - root - ERROR - Traceback (most recent call last):

2020-01-13 09:50:31,535 - root - ERROR - Traceback (most recent call last):

2020-01-13 09:50:31,535 - root - ERROR - Traceback (most recent call last):

2020-01-13 09:50:31,535 - root - ERROR - Traceback (most recent call last):

2020-01-13 09:50:31,535 - root - ERROR - Traceback (most recent call last):

2020-01-13 09:50:31,535 - root - ERROR - Traceback (most recent call last):

2020-01-13 09:50:31,535 - root - ERROR - Traceback (most recent call last):

2020-01-13 09:50:31,535 - root - ERROR - Traceback (most recent call last):

2020-01-13 09:50:31,535 - root - ERROR - Traceback (most recent call last):

2020-01-13 09:50:31,535 - root - ERROR - Traceback (most recent call last):

2020-01-13 09:50:31,535 - root - ERROR - Traceback (most recent call last):

2020-01-13 09:50:31,535 - root - ERROR - Traceback (most recent call last):

2020-01-13 09:50:31,535 - root - ERROR - Traceback (most recent call last):

2020-01-13 09:50:31,535 - root - ERROR - Traceback (most recent call last):

2020-01-13 09:50:31,535 - root - ERROR - 
2020-01-13 09:50:31,535 - root - ERROR - 
2020-01-13 09:50:31,535 - root - ERROR - 
2020-01-13 09:50:31,535 - root - ERROR - 
2020-01-13 09:50:31,535 - root - ERROR - 
2020-01-13 09:50:31,535 - root - ERROR - 
2020-01-13 09:50:31,535 - root - ERROR - 
2020-01-13 09:50:31,535 - root - ERROR - 
2020-01-13 09:50:31,535 - root - ERROR - 
2020-01-13 09:50:31,535 - root - ERROR - 
2020-01-13 09:50:31,535 - root - ERROR - 
2020-01-13 09:50:31,535 - root - ERROR - 
2020-01-13 09:50:31,535 - root - ERROR - 
2020-01-13 09:50:31,535 - root - ERROR - 
2020-01-13 09:50:31,535 - root - ERROR -   File "tkinter\__init__.py", line 1883, in __call__

2020-01-13 09:50:31,535 - root - ERROR -   File "tkinter\__init__.py", line 1883, in __call__

2020-01-13 09:50:31,535 - root - ERROR -   File "tkinter\__init__.py", line 1883, in __call__

2020-01-13 09:50:31,535 - root - ERROR -   File "tkinter\__init__.py", line 1883, in __call__

2020-01-13 09:50:31,535 - root - ERROR -   File "tkinter\__init__.py", line 1883, in __call__

2020-01-13 09:50:31,535 - root - ERROR -   File "tkinter\__init__.py", line 1883, in __call__

2020-01-13 09:50:31,535 - root - ERROR -   File "tkinter\__init__.py", line 1883, in __call__

2020-01-13 09:50:31,535 - root - ERROR -   File "tkinter\__init__.py", line 1883, in __call__

2020-01-13 09:50:31,535 - root - ERROR -   File "tkinter\__init__.py", line 1883, in __call__

2020-01-13 09:50:31,535 - root - ERROR -   File "tkinter\__init__.py", line 1883, in __call__

2020-01-13 09:50:31,535 - root - ERROR -   File "tkinter\__init__.py", line 1883, in __call__

2020-01-13 09:50:31,535 - root - ERROR -   File "tkinter\__init__.py", line 1883, in __call__

2020-01-13 09:50:31,535 - root - ERROR -   File "tkinter\__init__.py", line 1883, in __call__

2020-01-13 09:50:31,535 - root - ERROR -   File "tkinter\__init__.py", line 1883, in __call__

2020-01-13 09:50:31,535 - root - ERROR - 
2020-01-13 09:50:31,535 - root - ERROR - 
2020-01-13 09:50:31,535 - root - ERROR - 
2020-01-13 09:50:31,535 - root - ERROR - 
2020-01-13 09:50:31,535 - root - ERROR - 
2020-01-13 09:50:31,535 - root - ERROR - 
2020-01-13 09:50:31,535 - root - ERROR - 
2020-01-13 09:50:31,535 - root - ERROR - 
2020-01-13 09:50:31,535 - root - ERROR - 
2020-01-13 09:50:31,535 - root - ERROR - 
2020-01-13 09:50:31,535 - root - ERROR - 
2020-01-13 09:50:31,535 - root - ERROR - 
2020-01-13 09:50:31,535 - root - ERROR - 
2020-01-13 09:50:31,535 - root - ERROR - 
2020-01-13 09:50:31,535 - root - ERROR -   File "service_book.pyw", line 1283, in add_scheduled_tasks

2020-01-13 09:50:31,535 - root - ERROR -   File "service_book.pyw", line 1283, in add_scheduled_tasks

2020-01-13 09:50:31,535 - root - ERROR -   File "service_book.pyw", line 1283, in add_scheduled_tasks

2020-01-13 09:50:31,535 - root - ERROR -   File "service_book.pyw", line 1283, in add_scheduled_tasks

2020-01-13 09:50:31,535 - root - ERROR -   File "service_book.pyw", line 1283, in add_scheduled_tasks

2020-01-13 09:50:31,535 - root - ERROR -   File "service_book.pyw", line 1283, in add_scheduled_tasks

2020-01-13 09:50:31,535 - root - ERROR -   File "service_book.pyw", line 1283, in add_scheduled_tasks

2020-01-13 09:50:31,535 - root - ERROR -   File "service_book.pyw", line 1283, in add_scheduled_tasks

2020-01-13 09:50:31,535 - root - ERROR -   File "service_book.pyw", line 1283, in add_scheduled_tasks

2020-01-13 09:50:31,535 - root - ERROR -   File "service_book.pyw", line 1283, in add_scheduled_tasks

2020-01-13 09:50:31,535 - root - ERROR -   File "service_book.pyw", line 1283, in add_scheduled_tasks

2020-01-13 09:50:31,535 - root - ERROR -   File "service_book.pyw", line 1283, in add_scheduled_tasks

2020-01-13 09:50:31,535 - root - ERROR -   File "service_book.pyw", line 1283, in add_scheduled_tasks

2020-01-13 09:50:31,535 - root - ERROR -   File "service_book.pyw", line 1283, in add_scheduled_tasks

2020-01-13 09:50:31,535 - root - ERROR - 
2020-01-13 09:50:31,535 - root - ERROR - 
2020-01-13 09:50:31,535 - root - ERROR - 
2020-01-13 09:50:31,535 - root - ERROR - 
2020-01-13 09:50:31,535 - root - ERROR - 
2020-01-13 09:50:31,535 - root - ERROR - 
2020-01-13 09:50:31,535 - root - ERROR - 
2020-01-13 09:50:31,535 - root - ERROR - 
2020-01-13 09:50:31,535 - root - ERROR - 
2020-01-13 09:50:31,535 - root - ERROR - 
2020-01-13 09:50:31,535 - root - ERROR - 
2020-01-13 09:50:31,535 - root - ERROR - 
2020-01-13 09:50:31,535 - root - ERROR - 
2020-01-13 09:50:31,535 - root - ERROR - 
2020-01-13 09:50:31,535 - root - ERROR -   File "add_task.py", line 151, in create_add_task_window

2020-01-13 09:50:31,535 - root - ERROR -   File "add_task.py", line 151, in create_add_task_window

2020-01-13 09:50:31,535 - root - ERROR -   File "add_task.py", line 151, in create_add_task_window

2020-01-13 09:50:31,535 - root - ERROR -   File "add_task.py", line 151, in create_add_task_window

2020-01-13 09:50:31,535 - root - ERROR -   File "add_task.py", line 151, in create_add_task_window

2020-01-13 09:50:31,535 - root - ERROR -   File "add_task.py", line 151, in create_add_task_window

2020-01-13 09:50:31,535 - root - ERROR -   File "add_task.py", line 151, in create_add_task_window

2020-01-13 09:50:31,535 - root - ERROR -   File "add_task.py", line 151, in create_add_task_window

2020-01-13 09:50:31,535 - root - ERROR -   File "add_task.py", line 151, in create_add_task_window

2020-01-13 09:50:31,535 - root - ERROR -   File "add_task.py", line 151, in create_add_task_window

2020-01-13 09:50:31,535 - root - ERROR -   File "add_task.py", line 151, in create_add_task_window

2020-01-13 09:50:31,535 - root - ERROR -   File "add_task.py", line 151, in create_add_task_window

2020-01-13 09:50:31,535 - root - ERROR -   File "add_task.py", line 151, in create_add_task_window

2020-01-13 09:50:31,535 - root - ERROR -   File "add_task.py", line 151, in create_add_task_window

2020-01-13 09:50:31,535 - root - ERROR - 
2020-01-13 09:50:31,535 - root - ERROR - 
2020-01-13 09:50:31,535 - root - ERROR - 
2020-01-13 09:50:31,535 - root - ERROR - 
2020-01-13 09:50:31,535 - root - ERROR - 
2020-01-13 09:50:31,535 - root - ERROR - 
2020-01-13 09:50:31,535 - root - ERROR - 
2020-01-13 09:50:31,535 - root - ERROR - 
2020-01-13 09:50:31,535 - root - ERROR - 
2020-01-13 09:50:31,535 - root - ERROR - 
2020-01-13 09:50:31,535 - root - ERROR - 
2020-01-13 09:50:31,535 - root - ERROR - 
2020-01-13 09:50:31,535 - root - ERROR - 
2020-01-13 09:50:31,535 - root - ERROR - 
2020-01-13 09:50:31,535 - root - ERROR -   File "add_task.py", line 447, in __init__

2020-01-13 09:50:31,535 - root - ERROR -   File "add_task.py", line 447, in __init__

2020-01-13 09:50:31,535 - root - ERROR -   File "add_task.py", line 447, in __init__

2020-01-13 09:50:31,535 - root - ERROR -   File "add_task.py", line 447, in __init__

2020-01-13 09:50:31,535 - root - ERROR -   File "add_task.py", line 447, in __init__

2020-01-13 09:50:31,535 - root - ERROR -   File "add_task.py", line 447, in __init__

2020-01-13 09:50:31,535 - root - ERROR -   File "add_task.py", line 447, in __init__

2020-01-13 09:50:31,535 - root - ERROR -   File "add_task.py", line 447, in __init__

2020-01-13 09:50:31,535 - root - ERROR -   File "add_task.py", line 447, in __init__

2020-01-13 09:50:31,535 - root - ERROR -   File "add_task.py", line 447, in __init__

2020-01-13 09:50:31,535 - root - ERROR -   File "add_task.py", line 447, in __init__

2020-01-13 09:50:31,535 - root - ERROR -   File "add_task.py", line 447, in __init__

2020-01-13 09:50:31,535 - root - ERROR -   File "add_task.py", line 447, in __init__

2020-01-13 09:50:31,535 - root - ERROR -   File "add_task.py", line 447, in __init__

2020-01-13 09:50:31,535 - root - ERROR - 
2020-01-13 09:50:31,535 - root - ERROR - 
2020-01-13 09:50:31,535 - root - ERROR - 
2020-01-13 09:50:31,535 - root - ERROR - 
2020-01-13 09:50:31,535 - root - ERROR - 
2020-01-13 09:50:31,535 - root - ERROR - 
2020-01-13 09:50:31,535 - root - ERROR - 
2020-01-13 09:50:31,535 - root - ERROR - 
2020-01-13 09:50:31,535 - root - ERROR - 
2020-01-13 09:50:31,535 - root - ERROR - 
2020-01-13 09:50:31,535 - root - ERROR - 
2020-01-13 09:50:31,535 - root - ERROR - 
2020-01-13 09:50:31,535 - root - ERROR - 
2020-01-13 09:50:31,535 - root - ERROR - 
2020-01-13 09:50:31,535 - root - ERROR -   File "add_task.py", line 488, in get_copier

2020-01-13 09:50:31,535 - root - ERROR -   File "add_task.py", line 488, in get_copier

2020-01-13 09:50:31,535 - root - ERROR -   File "add_task.py", line 488, in get_copier

2020-01-13 09:50:31,535 - root - ERROR -   File "add_task.py", line 488, in get_copier

2020-01-13 09:50:31,535 - root - ERROR -   File "add_task.py", line 488, in get_copier

2020-01-13 09:50:31,535 - root - ERROR -   File "add_task.py", line 488, in get_copier

2020-01-13 09:50:31,535 - root - ERROR -   File "add_task.py", line 488, in get_copier

2020-01-13 09:50:31,535 - root - ERROR -   File "add_task.py", line 488, in get_copier

2020-01-13 09:50:31,535 - root - ERROR -   File "add_task.py", line 488, in get_copier

2020-01-13 09:50:31,535 - root - ERROR -   File "add_task.py", line 488, in get_copier

2020-01-13 09:50:31,535 - root - ERROR -   File "add_task.py", line 488, in get_copier

2020-01-13 09:50:31,535 - root - ERROR -   File "add_task.py", line 488, in get_copier

2020-01-13 09:50:31,535 - root - ERROR -   File "add_task.py", line 488, in get_copier

2020-01-13 09:50:31,535 - root - ERROR -   File "add_task.py", line 488, in get_copier

2020-01-13 09:50:31,535 - root - ERROR - 
2020-01-13 09:50:31,535 - root - ERROR - 
2020-01-13 09:50:31,535 - root - ERROR - 
2020-01-13 09:50:31,535 - root - ERROR - 
2020-01-13 09:50:31,535 - root - ERROR - 
2020-01-13 09:50:31,535 - root - ERROR - 
2020-01-13 09:50:31,535 - root - ERROR - 
2020-01-13 09:50:31,535 - root - ERROR - 
2020-01-13 09:50:31,535 - root - ERROR - 
2020-01-13 09:50:31,535 - root - ERROR - 
2020-01-13 09:50:31,535 - root - ERROR - 
2020-01-13 09:50:31,535 - root - ERROR - 
2020-01-13 09:50:31,535 - root - ERROR - 
2020-01-13 09:50:31,535 - root - ERROR - 
2020-01-13 09:50:31,535 - root - ERROR - TypeError: can only concatenate str (not "NoneType") to str

2020-01-13 09:50:31,535 - root - ERROR - TypeError: can only concatenate str (not "NoneType") to str

2020-01-13 09:50:31,535 - root - ERROR - TypeError: can only concatenate str (not "NoneType") to str

2020-01-13 09:50:31,535 - root - ERROR - TypeError: can only concatenate str (not "NoneType") to str

2020-01-13 09:50:31,535 - root - ERROR - TypeError: can only concatenate str (not "NoneType") to str

2020-01-13 09:50:31,535 - root - ERROR - TypeError: can only concatenate str (not "NoneType") to str

2020-01-13 09:50:31,535 - root - ERROR - TypeError: can only concatenate str (not "NoneType") to str

2020-01-13 09:50:31,535 - root - ERROR - TypeError: can only concatenate str (not "NoneType") to str

2020-01-13 09:50:31,535 - root - ERROR - TypeError: can only concatenate str (not "NoneType") to str

2020-01-13 09:50:31,535 - root - ERROR - TypeError: can only concatenate str (not "NoneType") to str

2020-01-13 09:50:31,535 - root - ERROR - TypeError: can only concatenate str (not "NoneType") to str

2020-01-13 09:50:31,535 - root - ERROR - TypeError: can only concatenate str (not "NoneType") to str

2020-01-13 09:50:31,535 - root - ERROR - TypeError: can only concatenate str (not "NoneType") to str

2020-01-13 09:50:31,535 - root - ERROR - TypeError: can only concatenate str (not "NoneType") to str

2020-01-13 09:50:31,535 - root - ERROR - 
2020-01-13 09:50:31,535 - root - ERROR - 
2020-01-13 09:50:31,535 - root - ERROR - 
2020-01-13 09:50:31,535 - root - ERROR - 
2020-01-13 09:50:31,535 - root - ERROR - 
2020-01-13 09:50:31,535 - root - ERROR - 
2020-01-13 09:50:31,535 - root - ERROR - 
2020-01-13 09:50:31,535 - root - ERROR - 
2020-01-13 09:50:31,535 - root - ERROR - 
2020-01-13 09:50:31,535 - root - ERROR - 
2020-01-13 09:50:31,535 - root - ERROR - 
2020-01-13 09:50:31,535 - root - ERROR - 
2020-01-13 09:50:31,535 - root - ERROR - 
2020-01-13 09:50:31,535 - root - ERROR - 
2020-01-13 14:36:01,235 - root - ERROR - Exception in Tkinter callback
2020-01-13 14:36:01,235 - root - ERROR - Exception in Tkinter callback
2020-01-13 14:36:01,235 - root - ERROR - Exception in Tkinter callback
2020-01-13 14:36:01,235 - root - ERROR - Exception in Tkinter callback
2020-01-13 14:36:01,235 - root - ERROR - Exception in Tkinter callback
2020-01-13 14:36:01,235 - root - ERROR - Exception in Tkinter callback
2020-01-13 14:36:01,235 - root - ERROR - Exception in Tkinter callback
2020-01-13 14:36:01,235 - root - ERROR - Exception in Tkinter callback
2020-01-13 14:36:01,235 - root - ERROR - Exception in Tkinter callback
2020-01-13 14:36:01,235 - root - ERROR - Exception in Tkinter callback
2020-01-13 14:36:01,235 - root - ERROR - Exception in Tkinter callback
2020-01-13 14:36:01,235 - root - ERROR - Exception in Tkinter callback
2020-01-13 14:36:01,235 - root - ERROR - Exception in Tkinter callback
2020-01-13 14:36:01,235 - root - ERROR - Exception in Tkinter callback
2020-01-13 14:36:01,235 - root - ERROR - 

2020-01-13 14:36:01,235 - root - ERROR - 

2020-01-13 14:36:01,235 - root - ERROR - 

2020-01-13 14:36:01,235 - root - ERROR - 

2020-01-13 14:36:01,235 - root - ERROR - 

2020-01-13 14:36:01,235 - root - ERROR - 

2020-01-13 14:36:01,235 - root - ERROR - 

2020-01-13 14:36:01,235 - root - ERROR - 

2020-01-13 14:36:01,235 - root - ERROR - 

2020-01-13 14:36:01,235 - root - ERROR - 

2020-01-13 14:36:01,235 - root - ERROR - 

2020-01-13 14:36:01,235 - root - ERROR - 

2020-01-13 14:36:01,235 - root - ERROR - 

2020-01-13 14:36:01,235 - root - ERROR - 

2020-01-13 14:36:01,235 - root - ERROR - Traceback (most recent call last):

2020-01-13 14:36:01,235 - root - ERROR - Traceback (most recent call last):

2020-01-13 14:36:01,235 - root - ERROR - Traceback (most recent call last):

2020-01-13 14:36:01,235 - root - ERROR - Traceback (most recent call last):

2020-01-13 14:36:01,235 - root - ERROR - Traceback (most recent call last):

2020-01-13 14:36:01,235 - root - ERROR - Traceback (most recent call last):

2020-01-13 14:36:01,235 - root - ERROR - Traceback (most recent call last):

2020-01-13 14:36:01,235 - root - ERROR - Traceback (most recent call last):

2020-01-13 14:36:01,235 - root - ERROR - Traceback (most recent call last):

2020-01-13 14:36:01,235 - root - ERROR - Traceback (most recent call last):

2020-01-13 14:36:01,235 - root - ERROR - Traceback (most recent call last):

2020-01-13 14:36:01,235 - root - ERROR - Traceback (most recent call last):

2020-01-13 14:36:01,235 - root - ERROR - Traceback (most recent call last):

2020-01-13 14:36:01,235 - root - ERROR - Traceback (most recent call last):

2020-01-13 14:36:01,235 - root - ERROR - 
2020-01-13 14:36:01,235 - root - ERROR - 
2020-01-13 14:36:01,235 - root - ERROR - 
2020-01-13 14:36:01,235 - root - ERROR - 
2020-01-13 14:36:01,235 - root - ERROR - 
2020-01-13 14:36:01,235 - root - ERROR - 
2020-01-13 14:36:01,235 - root - ERROR - 
2020-01-13 14:36:01,235 - root - ERROR - 
2020-01-13 14:36:01,235 - root - ERROR - 
2020-01-13 14:36:01,235 - root - ERROR - 
2020-01-13 14:36:01,235 - root - ERROR - 
2020-01-13 14:36:01,235 - root - ERROR - 
2020-01-13 14:36:01,235 - root - ERROR - 
2020-01-13 14:36:01,235 - root - ERROR - 
2020-01-13 14:36:01,235 - root - ERROR -   File "tkinter\__init__.py", line 1883, in __call__

2020-01-13 14:36:01,235 - root - ERROR -   File "tkinter\__init__.py", line 1883, in __call__

2020-01-13 14:36:01,235 - root - ERROR -   File "tkinter\__init__.py", line 1883, in __call__

2020-01-13 14:36:01,235 - root - ERROR -   File "tkinter\__init__.py", line 1883, in __call__

2020-01-13 14:36:01,235 - root - ERROR -   File "tkinter\__init__.py", line 1883, in __call__

2020-01-13 14:36:01,235 - root - ERROR -   File "tkinter\__init__.py", line 1883, in __call__

2020-01-13 14:36:01,235 - root - ERROR -   File "tkinter\__init__.py", line 1883, in __call__

2020-01-13 14:36:01,235 - root - ERROR -   File "tkinter\__init__.py", line 1883, in __call__

2020-01-13 14:36:01,235 - root - ERROR -   File "tkinter\__init__.py", line 1883, in __call__

2020-01-13 14:36:01,235 - root - ERROR -   File "tkinter\__init__.py", line 1883, in __call__

2020-01-13 14:36:01,235 - root - ERROR -   File "tkinter\__init__.py", line 1883, in __call__

2020-01-13 14:36:01,235 - root - ERROR -   File "tkinter\__init__.py", line 1883, in __call__

2020-01-13 14:36:01,235 - root - ERROR -   File "tkinter\__init__.py", line 1883, in __call__

2020-01-13 14:36:01,235 - root - ERROR -   File "tkinter\__init__.py", line 1883, in __call__

2020-01-13 14:36:01,235 - root - ERROR - 
2020-01-13 14:36:01,235 - root - ERROR - 
2020-01-13 14:36:01,235 - root - ERROR - 
2020-01-13 14:36:01,235 - root - ERROR - 
2020-01-13 14:36:01,235 - root - ERROR - 
2020-01-13 14:36:01,235 - root - ERROR - 
2020-01-13 14:36:01,235 - root - ERROR - 
2020-01-13 14:36:01,235 - root - ERROR - 
2020-01-13 14:36:01,235 - root - ERROR - 
2020-01-13 14:36:01,235 - root - ERROR - 
2020-01-13 14:36:01,235 - root - ERROR - 
2020-01-13 14:36:01,235 - root - ERROR - 
2020-01-13 14:36:01,235 - root - ERROR - 
2020-01-13 14:36:01,235 - root - ERROR - 
2020-01-13 14:36:01,235 - root - ERROR -   File "service_book.pyw", line 1302, in edit_scheduled_tasks

2020-01-13 14:36:01,235 - root - ERROR -   File "service_book.pyw", line 1302, in edit_scheduled_tasks

2020-01-13 14:36:01,235 - root - ERROR -   File "service_book.pyw", line 1302, in edit_scheduled_tasks

2020-01-13 14:36:01,235 - root - ERROR -   File "service_book.pyw", line 1302, in edit_scheduled_tasks

2020-01-13 14:36:01,235 - root - ERROR -   File "service_book.pyw", line 1302, in edit_scheduled_tasks

2020-01-13 14:36:01,235 - root - ERROR -   File "service_book.pyw", line 1302, in edit_scheduled_tasks

2020-01-13 14:36:01,235 - root - ERROR -   File "service_book.pyw", line 1302, in edit_scheduled_tasks

2020-01-13 14:36:01,235 - root - ERROR -   File "service_book.pyw", line 1302, in edit_scheduled_tasks

2020-01-13 14:36:01,235 - root - ERROR -   File "service_book.pyw", line 1302, in edit_scheduled_tasks

2020-01-13 14:36:01,235 - root - ERROR -   File "service_book.pyw", line 1302, in edit_scheduled_tasks

2020-01-13 14:36:01,235 - root - ERROR -   File "service_book.pyw", line 1302, in edit_scheduled_tasks

2020-01-13 14:36:01,235 - root - ERROR -   File "service_book.pyw", line 1302, in edit_scheduled_tasks

2020-01-13 14:36:01,235 - root - ERROR -   File "service_book.pyw", line 1302, in edit_scheduled_tasks

2020-01-13 14:36:01,235 - root - ERROR -   File "service_book.pyw", line 1302, in edit_scheduled_tasks

2020-01-13 14:36:01,235 - root - ERROR - 
2020-01-13 14:36:01,235 - root - ERROR - 
2020-01-13 14:36:01,235 - root - ERROR - 
2020-01-13 14:36:01,235 - root - ERROR - 
2020-01-13 14:36:01,235 - root - ERROR - 
2020-01-13 14:36:01,235 - root - ERROR - 
2020-01-13 14:36:01,235 - root - ERROR - 
2020-01-13 14:36:01,235 - root - ERROR - 
2020-01-13 14:36:01,235 - root - ERROR - 
2020-01-13 14:36:01,235 - root - ERROR - 
2020-01-13 14:36:01,235 - root - ERROR - 
2020-01-13 14:36:01,235 - root - ERROR - 
2020-01-13 14:36:01,235 - root - ERROR - 
2020-01-13 14:36:01,235 - root - ERROR - 
2020-01-13 14:36:01,235 - root - ERROR -   File "edit_task.py", line 97, in create_edit_task_window

2020-01-13 14:36:01,235 - root - ERROR -   File "edit_task.py", line 97, in create_edit_task_window

2020-01-13 14:36:01,235 - root - ERROR -   File "edit_task.py", line 97, in create_edit_task_window

2020-01-13 14:36:01,235 - root - ERROR -   File "edit_task.py", line 97, in create_edit_task_window

2020-01-13 14:36:01,235 - root - ERROR -   File "edit_task.py", line 97, in create_edit_task_window

2020-01-13 14:36:01,235 - root - ERROR -   File "edit_task.py", line 97, in create_edit_task_window

2020-01-13 14:36:01,235 - root - ERROR -   File "edit_task.py", line 97, in create_edit_task_window

2020-01-13 14:36:01,235 - root - ERROR -   File "edit_task.py", line 97, in create_edit_task_window

2020-01-13 14:36:01,235 - root - ERROR -   File "edit_task.py", line 97, in create_edit_task_window

2020-01-13 14:36:01,235 - root - ERROR -   File "edit_task.py", line 97, in create_edit_task_window

2020-01-13 14:36:01,235 - root - ERROR -   File "edit_task.py", line 97, in create_edit_task_window

2020-01-13 14:36:01,235 - root - ERROR -   File "edit_task.py", line 97, in create_edit_task_window

2020-01-13 14:36:01,235 - root - ERROR -   File "edit_task.py", line 97, in create_edit_task_window

2020-01-13 14:36:01,235 - root - ERROR -   File "edit_task.py", line 97, in create_edit_task_window

2020-01-13 14:36:01,235 - root - ERROR - 
2020-01-13 14:36:01,235 - root - ERROR - 
2020-01-13 14:36:01,235 - root - ERROR - 
2020-01-13 14:36:01,235 - root - ERROR - 
2020-01-13 14:36:01,235 - root - ERROR - 
2020-01-13 14:36:01,235 - root - ERROR - 
2020-01-13 14:36:01,235 - root - ERROR - 
2020-01-13 14:36:01,235 - root - ERROR - 
2020-01-13 14:36:01,235 - root - ERROR - 
2020-01-13 14:36:01,235 - root - ERROR - 
2020-01-13 14:36:01,235 - root - ERROR - 
2020-01-13 14:36:01,235 - root - ERROR - 
2020-01-13 14:36:01,235 - root - ERROR - 
2020-01-13 14:36:01,235 - root - ERROR - 
2020-01-13 14:36:01,235 - root - ERROR -   File "edit_task.py", line 662, in __init__

2020-01-13 14:36:01,235 - root - ERROR -   File "edit_task.py", line 662, in __init__

2020-01-13 14:36:01,235 - root - ERROR -   File "edit_task.py", line 662, in __init__

2020-01-13 14:36:01,235 - root - ERROR -   File "edit_task.py", line 662, in __init__

2020-01-13 14:36:01,235 - root - ERROR -   File "edit_task.py", line 662, in __init__

2020-01-13 14:36:01,235 - root - ERROR -   File "edit_task.py", line 662, in __init__

2020-01-13 14:36:01,235 - root - ERROR -   File "edit_task.py", line 662, in __init__

2020-01-13 14:36:01,235 - root - ERROR -   File "edit_task.py", line 662, in __init__

2020-01-13 14:36:01,235 - root - ERROR -   File "edit_task.py", line 662, in __init__

2020-01-13 14:36:01,235 - root - ERROR -   File "edit_task.py", line 662, in __init__

2020-01-13 14:36:01,235 - root - ERROR -   File "edit_task.py", line 662, in __init__

2020-01-13 14:36:01,235 - root - ERROR -   File "edit_task.py", line 662, in __init__

2020-01-13 14:36:01,235 - root - ERROR -   File "edit_task.py", line 662, in __init__

2020-01-13 14:36:01,235 - root - ERROR -   File "edit_task.py", line 662, in __init__

2020-01-13 14:36:01,235 - root - ERROR - 
2020-01-13 14:36:01,235 - root - ERROR - 
2020-01-13 14:36:01,235 - root - ERROR - 
2020-01-13 14:36:01,235 - root - ERROR - 
2020-01-13 14:36:01,235 - root - ERROR - 
2020-01-13 14:36:01,235 - root - ERROR - 
2020-01-13 14:36:01,235 - root - ERROR - 
2020-01-13 14:36:01,235 - root - ERROR - 
2020-01-13 14:36:01,235 - root - ERROR - 
2020-01-13 14:36:01,235 - root - ERROR - 
2020-01-13 14:36:01,235 - root - ERROR - 
2020-01-13 14:36:01,235 - root - ERROR - 
2020-01-13 14:36:01,235 - root - ERROR - 
2020-01-13 14:36:01,235 - root - ERROR - 
2020-01-13 14:36:01,235 - root - ERROR -   File "tkinter\__init__.py", line 4061, in __init__

2020-01-13 14:36:01,235 - root - ERROR -   File "tkinter\__init__.py", line 4061, in __init__

2020-01-13 14:36:01,235 - root - ERROR -   File "tkinter\__init__.py", line 4061, in __init__

2020-01-13 14:36:01,235 - root - ERROR -   File "tkinter\__init__.py", line 4061, in __init__

2020-01-13 14:36:01,235 - root - ERROR -   File "tkinter\__init__.py", line 4061, in __init__

2020-01-13 14:36:01,235 - root - ERROR -   File "tkinter\__init__.py", line 4061, in __init__

2020-01-13 14:36:01,235 - root - ERROR -   File "tkinter\__init__.py", line 4061, in __init__

2020-01-13 14:36:01,235 - root - ERROR -   File "tkinter\__init__.py", line 4061, in __init__

2020-01-13 14:36:01,235 - root - ERROR -   File "tkinter\__init__.py", line 4061, in __init__

2020-01-13 14:36:01,235 - root - ERROR -   File "tkinter\__init__.py", line 4061, in __init__

2020-01-13 14:36:01,235 - root - ERROR -   File "tkinter\__init__.py", line 4061, in __init__

2020-01-13 14:36:01,235 - root - ERROR -   File "tkinter\__init__.py", line 4061, in __init__

2020-01-13 14:36:01,235 - root - ERROR -   File "tkinter\__init__.py", line 4061, in __init__

2020-01-13 14:36:01,235 - root - ERROR -   File "tkinter\__init__.py", line 4061, in __init__

2020-01-13 14:36:01,235 - root - ERROR - 
2020-01-13 14:36:01,235 - root - ERROR - 
2020-01-13 14:36:01,235 - root - ERROR - 
2020-01-13 14:36:01,235 - root - ERROR - 
2020-01-13 14:36:01,235 - root - ERROR - 
2020-01-13 14:36:01,235 - root - ERROR - 
2020-01-13 14:36:01,235 - root - ERROR - 
2020-01-13 14:36:01,235 - root - ERROR - 
2020-01-13 14:36:01,235 - root - ERROR - 
2020-01-13 14:36:01,235 - root - ERROR - 
2020-01-13 14:36:01,235 - root - ERROR - 
2020-01-13 14:36:01,235 - root - ERROR - 
2020-01-13 14:36:01,235 - root - ERROR - 
2020-01-13 14:36:01,235 - root - ERROR - 
2020-01-13 14:36:01,235 - root - ERROR -   File "tkinter\__init__.py", line 4006, in __init__

2020-01-13 14:36:01,235 - root - ERROR -   File "tkinter\__init__.py", line 4006, in __init__

2020-01-13 14:36:01,235 - root - ERROR -   File "tkinter\__init__.py", line 4006, in __init__

2020-01-13 14:36:01,235 - root - ERROR -   File "tkinter\__init__.py", line 4006, in __init__

2020-01-13 14:36:01,235 - root - ERROR -   File "tkinter\__init__.py", line 4006, in __init__

2020-01-13 14:36:01,235 - root - ERROR -   File "tkinter\__init__.py", line 4006, in __init__

2020-01-13 14:36:01,235 - root - ERROR -   File "tkinter\__init__.py", line 4006, in __init__

2020-01-13 14:36:01,235 - root - ERROR -   File "tkinter\__init__.py", line 4006, in __init__

2020-01-13 14:36:01,235 - root - ERROR -   File "tkinter\__init__.py", line 4006, in __init__

2020-01-13 14:36:01,235 - root - ERROR -   File "tkinter\__init__.py", line 4006, in __init__

2020-01-13 14:36:01,235 - root - ERROR -   File "tkinter\__init__.py", line 4006, in __init__

2020-01-13 14:36:01,235 - root - ERROR -   File "tkinter\__init__.py", line 4006, in __init__

2020-01-13 14:36:01,235 - root - ERROR -   File "tkinter\__init__.py", line 4006, in __init__

2020-01-13 14:36:01,235 - root - ERROR -   File "tkinter\__init__.py", line 4006, in __init__

2020-01-13 14:36:01,235 - root - ERROR - 
2020-01-13 14:36:01,235 - root - ERROR - 
2020-01-13 14:36:01,235 - root - ERROR - 
2020-01-13 14:36:01,235 - root - ERROR - 
2020-01-13 14:36:01,235 - root - ERROR - 
2020-01-13 14:36:01,235 - root - ERROR - 
2020-01-13 14:36:01,235 - root - ERROR - 
2020-01-13 14:36:01,235 - root - ERROR - 
2020-01-13 14:36:01,235 - root - ERROR - 
2020-01-13 14:36:01,235 - root - ERROR - 
2020-01-13 14:36:01,235 - root - ERROR - 
2020-01-13 14:36:01,235 - root - ERROR - 
2020-01-13 14:36:01,235 - root - ERROR - 
2020-01-13 14:36:01,235 - root - ERROR - 
2020-01-13 14:36:01,235 - root - ERROR - _tkinter.TclError: couldn't open "icons/view_files.png": no such file or directory

2020-01-13 14:36:01,235 - root - ERROR - _tkinter.TclError: couldn't open "icons/view_files.png": no such file or directory

2020-01-13 14:36:01,235 - root - ERROR - _tkinter.TclError: couldn't open "icons/view_files.png": no such file or directory

2020-01-13 14:36:01,235 - root - ERROR - _tkinter.TclError: couldn't open "icons/view_files.png": no such file or directory

2020-01-13 14:36:01,235 - root - ERROR - _tkinter.TclError: couldn't open "icons/view_files.png": no such file or directory

2020-01-13 14:36:01,235 - root - ERROR - _tkinter.TclError: couldn't open "icons/view_files.png": no such file or directory

2020-01-13 14:36:01,235 - root - ERROR - _tkinter.TclError: couldn't open "icons/view_files.png": no such file or directory

2020-01-13 14:36:01,235 - root - ERROR - _tkinter.TclError: couldn't open "icons/view_files.png": no such file or directory

2020-01-13 14:36:01,235 - root - ERROR - _tkinter.TclError: couldn't open "icons/view_files.png": no such file or directory

2020-01-13 14:36:01,235 - root - ERROR - _tkinter.TclError: couldn't open "icons/view_files.png": no such file or directory

2020-01-13 14:36:01,235 - root - ERROR - _tkinter.TclError: couldn't open "icons/view_files.png": no such file or directory

2020-01-13 14:36:01,235 - root - ERROR - _tkinter.TclError: couldn't open "icons/view_files.png": no such file or directory

2020-01-13 14:36:01,235 - root - ERROR - _tkinter.TclError: couldn't open "icons/view_files.png": no such file or directory

2020-01-13 14:36:01,235 - root - ERROR - _tkinter.TclError: couldn't open "icons/view_files.png": no such file or directory

2020-01-13 14:36:01,235 - root - ERROR - 
2020-01-13 14:36:01,235 - root - ERROR - 
2020-01-13 14:36:01,235 - root - ERROR - 
2020-01-13 14:36:01,235 - root - ERROR - 
2020-01-13 14:36:01,235 - root - ERROR - 
2020-01-13 14:36:01,235 - root - ERROR - 
2020-01-13 14:36:01,235 - root - ERROR - 
2020-01-13 14:36:01,235 - root - ERROR - 
2020-01-13 14:36:01,235 - root - ERROR - 
2020-01-13 14:36:01,235 - root - ERROR - 
2020-01-13 14:36:01,235 - root - ERROR - 
2020-01-13 14:36:01,235 - root - ERROR - 
2020-01-13 14:36:01,235 - root - ERROR - 
2020-01-13 14:36:01,235 - root - ERROR - 
